[32m2023-10-30 15:10:48 +0000[0m - dagster - [34mDEBUG[0m - __ASSET_JOB - 2bd257f2-491b-4b83-bef0-517266799129 - 12132 - LOGS_CAPTURED - Started capturing logs in process (pid: 12132).
[32m2023-10-30 15:10:48 +0000[0m - dagster - [34mDEBUG[0m - __ASSET_JOB - 2bd257f2-491b-4b83-bef0-517266799129 - 12132 - knmi_uurgegevens - STEP_START - Started execution of step "knmi_uurgegevens".
[32m2023-10-30 15:10:48 +0000[0m - dagster - [34mERROR[0m - [31m__ASSET_JOB - 2bd257f2-491b-4b83-bef0-517266799129 - 12132 - knmi_uurgegevens - STEP_FAILURE - Execution of step "knmi_uurgegevens" failed.

dagster._core.errors.DagsterExecutionStepExecutionError: Error occurred while executing op "knmi_uurgegevens"::

requests.exceptions.JSONDecodeError: Expecting value: line 1 column 1 (char 0)

Stack Trace:
  File "/usr/local/lib/python3.10/site-packages/dagster/_core/execution/plan/utils.py", line 54, in op_execution_error_boundary
    yield
  File "/usr/local/lib/python3.10/site-packages/dagster/_utils/__init__.py", line 461, in iterate_with_context
    next_output = next(iterator)
  File "/usr/local/lib/python3.10/site-packages/dagster/_core/execution/plan/compute_generator.py", line 131, in _coerce_op_compute_fn_to_iterator
    result = invoke_compute_fn(
  File "/usr/local/lib/python3.10/site-packages/dagster/_core/execution/plan/compute_generator.py", line 125, in invoke_compute_fn
    return fn(context, **args_to_pass) if context_arg_provided else fn(**args_to_pass)
  File "/workspaces/DSP/src/dsp-dagster/dsp_dagster/assets/knmi_data.py", line 47, in get_knmi_uurgegevens
    data = response.json()
  File "/usr/local/lib/python3.10/site-packages/requests/models.py", line 975, in json
    raise RequestsJSONDecodeError(e.msg, e.doc, e.pos)

The above exception occurred during handling of the following exception:
json.decoder.JSONDecodeError: Expecting value: line 1 column 1 (char 0)

Stack Trace:
  File "/usr/local/lib/python3.10/site-packages/requests/models.py", line 971, in json
    return complexjson.loads(self.text, **kwargs)
  File "/usr/local/lib/python3.10/json/__init__.py", line 346, in loads
    return _default_decoder.decode(s)
  File "/usr/local/lib/python3.10/json/decoder.py", line 337, in decode
    obj, end = self.raw_decode(s, idx=_w(s, 0).end())
  File "/usr/local/lib/python3.10/json/decoder.py", line 355, in raw_decode
    raise JSONDecodeError("Expecting value", s, err.value) from None

The above exception occurred during handling of the following exception:
StopIteration: 0

Stack Trace:
  File "/usr/local/lib/python3.10/json/decoder.py", line 353, in raw_decode
    obj, end = self.scan_once(s, idx)
[0m
